<?xml version="1.0" ?>
<!-- =================================================================================== -->
<!-- |    This document was autogenerated by xacro from donkey.gazebo.urdf.xacro       | -->
<!-- |    EDITING THIS FILE BY HAND IS NOT RECOMMENDED                                 | -->
<!-- =================================================================================== -->
<robot name="iai_donkey" xmlns:xacro="http://ros.org/wiki/xacro">
  <link name="arm_base">
    <!-- visual -->
    <visual>
      <geometry>
        <mesh filename="package://iai_sherpa_donkey/meshes/arm_base_vis.dae"/>
      </geometry>
    </visual>
    <!-- collision -->
    <collision>
      <geometry>
        <mesh filename="package://iai_sherpa_donkey/meshes/arm_base_col.stl"/>
      </geometry>
    </collision>
    <!-- inertial -->
    <inertial>
      <origin rpy="0 0 0" xyz="0 0 0"/>
      <mass value="0.5"/>
      <inertia ixx="0.001" ixy="0.0" ixz="0.0" iyy="0.001" iyz="0.0" izz="0.001"/>
    </inertial>
  </link>
  <joint name="base_link_arm_base_joint" type="revolute">
    <parent link="base_link"/>
    <child link="arm_base"/>
    <origin rpy="0 0 3.14159393311" xyz="-0.39818906784057617 0.0 0.0010514259338378906"/>
    <axis xyz="1 0 0"/>
    <!-- 
        THIS is a dirty hack must be fixed in future versions
        what we need is a new empty type which has properties for joint types limits...
        lower and upper could be set by constraints    
    -->
    <limit effort="100" lower="-3.14" upper="3.14" velocity="1.0"/>
  </joint>
  <transmission name="base_link_arm_base_trans">
    <type>position_controllers/JointTrajectoryController</type>
    <joint name="base_link_arm_base_joint">
      <hardwareInterface>PositionJointInterface</hardwareInterface>
    </joint>
    <actuator name="base_link_arm_base_motor">
      <hardwareInterface>PositionJointInterface</hardwareInterface>
      <mechanicalReduction>1</mechanicalReduction>
    </actuator>
  </transmission>
  <link name="arm_lower">
    <!-- visual -->
    <visual>
      <geometry>
        <mesh filename="package://iai_sherpa_donkey/meshes/arm_lower_vis.dae"/>
      </geometry>
    </visual>
    <!-- collision -->
    <collision>
      <geometry>
        <mesh filename="package://iai_sherpa_donkey/meshes/arm_lower_col.stl"/>
      </geometry>
    </collision>
    <!-- inertial -->
    <inertial>
      <origin rpy="0 0 0" xyz="0 0 0"/>
      <mass value="1"/>
      <inertia ixx="0.001" ixy="0.0" ixz="0.0" iyy="0.001" iyz="0.0" izz="0.001"/>
    </inertial>
  </link>
  <joint name="arm_base_arm_lower_joint" type="revolute">
    <parent link="arm_base"/>
    <child link="arm_lower"/>
    <origin rpy=" -0.0000  -0.8205  -0.0000" xyz="  0.1376   0.0000   0.0004"/>
    <axis xyz="0 1 0"/>
    <!-- 
        THIS is a dirty hack must be fixed in future versions
        what we need is a new empty type which has properties for joint types limits...
        lower and upper could be set by constraints    
    -->
    <limit effort="100" lower="-3.14" upper="3.14" velocity="1.0"/>
  </joint>
  <transmission name="arm_base_arm_lower_trans">
    <type>position_controllers/JointTrajectoryController</type>
    <joint name="arm_base_arm_lower_joint">
      <hardwareInterface>PositionJointInterface</hardwareInterface>
    </joint>
    <actuator name="arm_base_arm_lower_motor">
      <hardwareInterface>PositionJointInterface</hardwareInterface>
      <mechanicalReduction>1</mechanicalReduction>
    </actuator>
  </transmission>
  <link name="arm_lower_end">
    <!-- visual -->
    <visual>
      <geometry>
        <mesh filename="package://iai_sherpa_donkey/meshes/arm_lower_end_vis.dae"/>
      </geometry>
    </visual>
    <!-- collision -->
    <collision>
      <geometry>
        <mesh filename="package://iai_sherpa_donkey/meshes/arm_lower_end_col.stl"/>
      </geometry>
    </collision>
    <!-- inertial -->
    <inertial>
      <origin rpy="0 0 0" xyz="0 0 0"/>
      <mass value="0.5"/>
      <inertia ixx="0.001" ixy="0.0" ixz="0.0" iyy="0.001" iyz="0.0" izz="0.001"/>
    </inertial>
  </link>
  <joint name="arm_lower_arm_lower_end_joint" type="revolute">
    <parent link="arm_lower"/>
    <child link="arm_lower_end"/>
    <origin rpy=" -3.1416   0.0037  -0.0000" xyz="  0.5271   0.0000  -0.0025"/>
    <axis xyz="1 0 0"/>
    <!-- 
        THIS is a dirty hack must be fixed in future versions
        what we need is a new empty type which has properties for joint types limits...
        lower and upper could be set by constraints    
    -->
    <limit effort="100" lower="-3.14" upper="3.14" velocity="1.0"/>
  </joint>
  <transmission name="arm_lower_arm_lower_end_trans">
    <type>position_controllers/JointTrajectoryController</type>
    <joint name="arm_lower_arm_lower_end_joint">
      <hardwareInterface>PositionJointInterface</hardwareInterface>
    </joint>
    <actuator name="arm_lower_arm_lower_end_motor">
      <hardwareInterface>PositionJointInterface</hardwareInterface>
      <mechanicalReduction>1</mechanicalReduction>
    </actuator>
  </transmission>
  <link name="arm_upper">
    <!-- visual -->
    <visual>
      <geometry>
        <mesh filename="package://iai_sherpa_donkey/meshes/arm_upper_vis.dae"/>
      </geometry>
    </visual>
    <!-- collision -->
    <collision>
      <geometry>
        <mesh filename="package://iai_sherpa_donkey/meshes/arm_upper_col.stl"/>
      </geometry>
    </collision>
    <!-- inertial -->
    <inertial>
      <origin rpy="0 0 0" xyz="0 0 0"/>
      <mass value="2"/>
      <inertia ixx="0.001" ixy="0.0" ixz="0.0" iyy="0.001" iyz="0.0" izz="0.001"/>
    </inertial>
  </link>
  <joint name="arm_lower_end_arm_upper_joint" type="revolute">
    <parent link="arm_lower_end"/>
    <child link="arm_upper"/>
    <origin rpy=" -0.0000  -1.5348   0.0000" xyz="  0.0824  -0.0000   0.0412"/>
    <axis xyz="0 1 0"/>
    <!-- 
        THIS is a dirty hack must be fixed in future versions
        what we need is a new empty type which has properties for joint types limits...
        lower and upper could be set by constraints    
    -->
    <limit effort="100" lower="-3.14" upper="3.14" velocity="1.0"/>
  </joint>
  <transmission name="arm_lower_end_arm_upper_trans">
    <type>position_controllers/JointTrajectoryController</type>
    <joint name="arm_lower_end_arm_upper_joint">
      <hardwareInterface>PositionJointInterface</hardwareInterface>
    </joint>
    <actuator name="arm_lower_end_arm_upper_motor">
      <hardwareInterface>PositionJointInterface</hardwareInterface>
      <mechanicalReduction>1</mechanicalReduction>
    </actuator>
  </transmission>
  <link name="arm_upper_end">
    <!-- visual -->
    <visual>
      <geometry>
        <mesh filename="package://iai_sherpa_donkey/meshes/arm_upper_end_vis.dae"/>
      </geometry>
    </visual>
    <!-- collision -->
    <collision>
      <geometry>
        <mesh filename="package://iai_sherpa_donkey/meshes/arm_upper_end_col.stl"/>
      </geometry>
    </collision>
    <!-- inertial -->
    <inertial>
      <origin rpy="0 0 0" xyz="0 0 0"/>
      <mass value="20.5"/>
      <inertia ixx="0.001" ixy="0.0" ixz="0.0" iyy="0.001" iyz="0.0" izz="0.001"/>
    </inertial>
  </link>
  <joint name="arm_upper_arm_upper_end_joint" type="revolute">
    <parent link="arm_upper"/>
    <child link="arm_upper_end"/>
    <origin rpy="  3.1416  -0.0951   0.0000" xyz="  0.4170   0.0000   0.0075"/>
    <axis xyz="1 0 0"/>
    <!-- 
        THIS is a dirty hack must be fixed in future versions
        what we need is a new empty type which has properties for joint types limits...
        lower and upper could be set by constraints    
    -->
    <limit effort="100" lower="-3.14" upper="3.14" velocity="1.0"/>
  </joint>
  <transmission name="arm_upper_arm_upper_end_trans">
    <type>position_controllers/JointTrajectoryController</type>
    <joint name="arm_upper_arm_upper_end_joint">
      <hardwareInterface>PositionJointInterface</hardwareInterface>
    </joint>
    <actuator name="arm_upper_arm_upper_end_motor">
      <hardwareInterface>PositionJointInterface</hardwareInterface>
      <mechanicalReduction>1</mechanicalReduction>
    </actuator>
  </transmission>
  <link name="gripper_base">
    <visual>
      <geometry>
        <mesh filename="package://iai_sherpa_donkey/meshes/gripper_base_vis.dae"/>
      </geometry>
    </visual>
    <collision>
      <geometry>
        <mesh filename="package://iai_sherpa_donkey/meshes/gripper_base_col.stl"/>
      </geometry>
    </collision>
    <inertial>
      <origin rpy="0 0 0" xyz="0 0 0"/>
      <mass value="0.5"/>
      <inertia ixx="0.001" ixy="0.0" ixz="0.0" iyy="0.001" iyz="0.0" izz="0.001"/>
    </inertial>
  </link>
  <joint name="arm_upper_end_gripper_base_joint" type="revolute">
    <parent link="arm_upper_end"/>
    <child link="gripper_base"/>
    <origin rpy=" -0.0000  -0.8131   0.0000" xyz="  0.0824   0.0000   0.0014"/>
    <axis xyz="0 1 0"/>
    <!-- 
	    THIS is a dirty hack must be fixed in future versions
	    what we need is a new empty type which has properties for joint types limits...
	    lower and upper could be set by constraints    
	-->
    <limit effort="100" lower="-3.14" upper="3.14" velocity="1.0"/>
  </joint>
  <transmission name="arm_upper_end_gripper_base_trans">
    <type>position_controllers/JointTrajectoryController</type>
    <joint name="arm_upper_end_gripper_base_joint">
      <hardwareInterface>PositionJointInterface</hardwareInterface>
    </joint>
    <actuator name="arm_upper_end_gripper_base_motor">
      <hardwareInterface>PositionJointInterface</hardwareInterface>
      <mechanicalReduction>1</mechanicalReduction>
    </actuator>
  </transmission>
  <link name="gripper_palm">
    <!-- visual -->
    <visual>
      <geometry>
        <mesh filename="package://iai_sherpa_donkey/meshes/gripper_palm_vis.dae"/>
      </geometry>
    </visual>
    <!-- collision -->
    <!-- inertial -->
    <inertial>
      <origin rpy="0 0 0" xyz="0 0 0"/>
      <mass value="0.25"/>
      <inertia ixx="0.0005" ixy="0.0" ixz="0.0" iyy="0.0005" iyz="0.0" izz="0.0005"/>
    </inertial>
  </link>
  <joint name="gripper_base_gripper_palm_joint" type="revolute">
    <parent link="gripper_base"/>
    <child link="gripper_palm"/>
    <origin rpy=" -0.0000  -0.0000   0.0000" xyz="  0.1216  -0.0022  -0.0009"/>
    <axis xyz="1 0 0"/>
    <!-- 
        THIS is a dirty hack must be fixed in future versions
        what we need is a new empty type which has properties for joint types limits...
        lower and upper could be set by constraints    
    -->
    <limit effort="100" lower="-3.14" upper="3.14" velocity="1.0"/>
  </joint>
  <transmission name="gripper_base_gripper_palm_trans">
    <type>position_controllers/JointTrajectoryController</type>
    <joint name="gripper_base_gripper_palm_joint">
      <hardwareInterface>PositionJointInterface</hardwareInterface>
    </joint>
    <actuator name="gripper_base_gripper_palm_motor">
      <hardwareInterface>PositionJointInterface</hardwareInterface>
      <mechanicalReduction>1</mechanicalReduction>
    </actuator>
  </transmission>
  <link name="gripper_grasp_link"/>
  <joint name="gripper_palm_gripper_grasp_joint" type="fixed">
    <parent link="gripper_palm"/>
    <child link="gripper_grasp_link"/>
    <origin rpy="1.57079696655 0.785398483276  1.57079696655" xyz="0.02 0.0 0.0"/>
  </joint>
  <link name="cam_right">
    <!-- visual -->
    <visual>
      <geometry>
        <mesh filename="package://iai_sherpa_donkey/meshes/cam_vis.dae"/>
      </geometry>
    </visual>
    <!-- collision -->
    <!-- inertial -->
    <inertial>
      <origin rpy="0 0 0" xyz="0 0 0"/>
      <mass value="0.01"/>
      <inertia ixx="0.000001" ixy="0.0" ixz="0.0" iyy="0.000001" iyz="0.0" izz="0.000001"/>
    </inertial>
  </link>
  <joint name="gripper_base_cam_right_joint" type="revolute">
    <parent link="gripper_base"/>
    <child link="cam_right"/>
    <origin rpy=" -0.0000  -0.0000   0.0000" xyz="  0.0981  -0.0794  -0.0006"/>
    <axis xyz="1 0 0"/>
    <limit effort="0" lower="0" upper="0" velocity="0"/>
  </joint>
  <transmission name="gripper_base_cam_right_trans">
    <type>position_controllers/JointTrajectoryController</type>
    <joint name="gripper_base_cam_right_joint">
      <hardwareInterface>EffortJointInterface</hardwareInterface>
    </joint>
    <actuator name="gripper_base_cam_right_motor">
      <hardwareInterface>EffortJointInterface</hardwareInterface>
      <mechanicalReduction>1</mechanicalReduction>
    </actuator>
  </transmission>
  <link name="cam_left">
    <!-- visual -->
    <visual>
      <geometry>
        <mesh filename="package://iai_sherpa_donkey/meshes/cam_vis.dae"/>
      </geometry>
    </visual>
    <!-- collision -->
    <!-- inertial -->
    <inertial>
      <origin rpy="0 0 0" xyz="0 0 0"/>
      <mass value="0.01"/>
      <inertia ixx="0.000001" ixy="0.0" ixz="0.0" iyy="0.000001" iyz="0.0" izz="0.000001"/>
    </inertial>
  </link>
  <joint name="gripper_base_cam_left_joint" type="revolute">
    <parent link="gripper_base"/>
    <child link="cam_left"/>
    <origin rpy=" -3.1415 0.0000  0.0000" xyz="  0.1016   0.0759  -0.0006"/>
    <axis xyz="1 0 0"/>
    <limit effort="0" lower="0" upper="0" velocity="0"/>
  </joint>
  <transmission name="gripper_base_cam_left_trans">
    <type>position_controllers/JointTrajectoryController</type>
    <joint name="gripper_base_cam_left_joint">
      <hardwareInterface>EffortJointInterface</hardwareInterface>
    </joint>
    <actuator name="gripper_base_cam_left_motor">
      <hardwareInterface>EffortJointInterface</hardwareInterface>
      <mechanicalReduction>1</mechanicalReduction>
    </actuator>
  </transmission>
  <link name="finger_bottom_left">
    <!-- visual -->
    <visual>
      <geometry>
        <mesh filename="package://iai_sherpa_donkey/meshes/finger_vis.dae"/>
      </geometry>
    </visual>
    <collision>
      <geometry>
        <mesh filename="package://iai_sherpa_donkey/meshes/finger_vis.dae"/>
      </geometry>
    </collision>
    <!-- collision -->
    <!-- inertial -->
    <inertial>
      <origin rpy="0 0 0" xyz="0 0 0"/>
      <mass value="0.01"/>
      <inertia ixx="0.000001" ixy="0.0" ixz="0.0" iyy="0.000001" iyz="0.0" izz="0.000001"/>
    </inertial>
  </link>
  <joint name="gripper_palm_finger_bottom_left_joint" type="revolute">
    <parent link="gripper_palm"/>
    <child link="finger_bottom_left"/>
    <origin rpy=" -2.3562  -0.0000  -0.0000" xyz="  0.0054   0.0244  -0.0222"/>
    <axis xyz="0 1 0"/>
    <!-- 
        THIS is a dirty hack must be fixed in future versions
        what we need is a new empty type which has properties for joint types limits...
        lower and upper could be set by constraints    
    -->
    <limit effort="100" lower="-1.4" upper="0.4" velocity="1.0"/>
  </joint>
  <transmission name="gripper_palm_finger_bottom_left_trans">
    <type>position_controllers/JointTrajectoryController</type>
    <joint name="gripper_palm_finger_bottom_left_joint">
      <hardwareInterface>PositionJointInterface</hardwareInterface>
    </joint>
    <actuator name="gripper_palm_finger_bottom_left_motor">
      <hardwareInterface>PositionJointInterface</hardwareInterface>
      <mechanicalReduction>1</mechanicalReduction>
    </actuator>
  </transmission>
  <link name="finger_bottom_right">
    <!-- visual -->
    <visual>
      <geometry>
        <mesh filename="package://iai_sherpa_donkey/meshes/finger_vis.dae"/>
      </geometry>
    </visual>
    <collision>
      <geometry>
        <mesh filename="package://iai_sherpa_donkey/meshes/finger_vis.dae"/>
      </geometry>
    </collision>
    <!-- collision -->
    <!-- inertial -->
    <inertial>
      <origin rpy="0 0 0" xyz="0 0 0"/>
      <mass value="0.01"/>
      <inertia ixx="0.000001" ixy="0.0" ixz="0.0" iyy="0.000001" iyz="0.0" izz="0.000001"/>
    </inertial>
  </link>
  <joint name="gripper_palm_finger_bottom_right_joint" type="revolute">
    <parent link="gripper_palm"/>
    <child link="finger_bottom_right"/>
    <origin rpy="  2.3562   0.0000  -0.0000" xyz="  0.0054  -0.0209  -0.0213"/>
    <axis xyz="0 1 0"/>
    <!-- 
        THIS is a dirty hack must be fixed in future versions
        what we need is a new empty type which has properties for joint types limits...
        lower and upper could be set by constraints    
    -->
    <limit effort="100" lower="-1.4" upper="0.4" velocity="1.0"/>
  </joint>
  <transmission name="gripper_palm_finger_bottom_right_trans">
    <type>position_controllers/JointTrajectoryController</type>
    <joint name="gripper_palm_finger_bottom_right_joint">
      <hardwareInterface>PositionJointInterface</hardwareInterface>
    </joint>
    <actuator name="gripper_palm_finger_bottom_right_motor">
      <hardwareInterface>PositionJointInterface</hardwareInterface>
      <mechanicalReduction>1</mechanicalReduction>
    </actuator>
  </transmission>
  <link name="finger_top_left">
    <!-- visual -->
    <visual>
      <geometry>
        <mesh filename="package://iai_sherpa_donkey/meshes/finger_vis.dae"/>
      </geometry>
    </visual>
    <collision>
      <geometry>
        <mesh filename="package://iai_sherpa_donkey/meshes/finger_vis.dae"/>
      </geometry>
    </collision>
    <!-- collision -->
    <!-- inertial -->
    <inertial>
      <origin rpy="0 0 0" xyz="0 0 0"/>
      <mass value="0.01"/>
      <inertia ixx="0.000001" ixy="0.0" ixz="0.0" iyy="0.000001" iyz="0.0" izz="0.000001"/>
    </inertial>
  </link>
  <joint name="gripper_palm_finger_top_left_joint" type="revolute">
    <parent link="gripper_palm"/>
    <child link="finger_top_left"/>
    <origin rpy=" -0.7854  -0.0000  -0.0000" xyz="  0.0054   0.0253   0.0231"/>
    <axis xyz="0 1 0"/>
    <!-- 
        THIS is a dirty hack must be fixed in future versions
        what we need is a new empty type which has properties for joint types limits...
        lower and upper could be set by constraints    
    -->
    <limit effort="100" lower="-1.4" upper="0.4" velocity="1.0"/>
  </joint>
  <transmission name="gripper_palm_finger_top_left_trans">
    <type>position_controllers/JointTrajectoryController</type>
    <joint name="gripper_palm_finger_top_left_joint">
      <hardwareInterface>PositionJointInterface</hardwareInterface>
    </joint>
    <actuator name="gripper_palm_finger_top_left_motor">
      <hardwareInterface>PositionJointInterface</hardwareInterface>
      <mechanicalReduction>1</mechanicalReduction>
    </actuator>
  </transmission>
  <link name="finger_top_right">
    <!-- visual -->
    <visual>
      <geometry>
        <mesh filename="package://iai_sherpa_donkey/meshes/finger_vis.dae"/>
      </geometry>
    </visual>
    <collision>
      <geometry>
        <mesh filename="package://iai_sherpa_donkey/meshes/finger_vis.dae"/>
      </geometry>
    </collision>
    <!-- collision -->
    <!-- inertial -->
    <inertial>
      <origin rpy="0 0 0" xyz="0 0 0"/>
      <mass value="0.01"/>
      <inertia ixx="0.000001" ixy="0.0" ixz="0.0" iyy="0.000001" iyz="0.0" izz="0.000001"/>
    </inertial>
  </link>
  <joint name="gripper_palm_finger_top_right_joint" type="revolute">
    <parent link="gripper_palm"/>
    <child link="finger_top_right"/>
    <origin rpy="  0.7854   0.0000  -0.0000" xyz="  0.0054  -0.0200   0.0240"/>
    <axis xyz="0 1 0"/>
    <!-- 
        THIS is a dirty hack must be fixed in future versions
        what we need is a new empty type which has properties for joint types limits...
        lower and upper could be set by constraints    
    -->
    <limit effort="100" lower="-1.4" upper="0.4" velocity="1.0"/>
  </joint>
  <transmission name="gripper_palm_finger_top_right_trans">
    <type>position_controllers/JointTrajectoryController</type>
    <joint name="gripper_palm_finger_top_right_joint">
      <hardwareInterface>PositionJointInterface</hardwareInterface>
    </joint>
    <actuator name="gripper_palm_finger_top_right_motor">
      <hardwareInterface>PositionJointInterface</hardwareInterface>
      <mechanicalReduction>1</mechanicalReduction>
    </actuator>
  </transmission>
  <link name="chains_loose_front_left">
    <visual>
      <geometry>
        <mesh filename="package://iai_sherpa_donkey/meshes/Loose_Wheel.dae"/>
      </geometry>
    </visual>
    <collision>
      <geometry>
        <mesh filename="package://iai_sherpa_donkey/meshes/Loose_Wheel_Col.dae"/>
      </geometry>
    </collision>
    <inertial>
      <origin rpy="0 0 0" xyz="0 0 0"/>
      <mass value="0.5"/>
      <inertia ixx="0.001" ixy="0.0" ixz="0.0" iyy="0.001" iyz="0.0" izz="0.001"/>
    </inertial>
  </link>
  <joint name="chains_joint_front_left" type="revolute">
    <parent link="base_link"/>
    <child link="chains_loose_front_left"/>
    <origin rpy="3.14159393311 0 0" xyz="0.696425437927 0.503306388855 -0.26314997673"/>
    <limit effort="-1" lower="1." upper="2." velocity="-1"/>
    <axis xyz="0 1 0"/>
  </joint>
  <transmission name="chain_trans_front_left">
    <type>position_controllers/JointTrajectoryController</type>
    <joint name="chains_joint_front_left">
      <hardwareInterface>PositionJointInterface</hardwareInterface>
    </joint>
    <actuator name="chain_motor_front_left">
      <hardwareInterface>PositionJointInterface</hardwareInterface>
      <mechanicalReduction>10</mechanicalReduction>
    </actuator>
  </transmission>
  <link name="chains_loose_front_right">
    <visual>
      <geometry>
        <mesh filename="package://iai_sherpa_donkey/meshes/Loose_Wheel.dae"/>
      </geometry>
    </visual>
    <collision>
      <geometry>
        <mesh filename="package://iai_sherpa_donkey/meshes/Loose_Wheel_Col.dae"/>
      </geometry>
    </collision>
    <inertial>
      <origin rpy="0 0 0" xyz="0 0 0"/>
      <mass value="0.5"/>
      <inertia ixx="0.001" ixy="0.0" ixz="0.0" iyy="0.001" iyz="0.0" izz="0.001"/>
    </inertial>
  </link>
  <joint name="chains_joint_front_right" type="revolute">
    <parent link="base_link"/>
    <child link="chains_loose_front_right"/>
    <origin rpy="0.0 0.0 0.0" xyz="0.696425437927 -0.503306388855 -0.26314997673"/>
    <limit effort="-1" lower="1." upper="2." velocity="-1"/>
    <axis xyz="0 -1 0"/>
  </joint>
  <transmission name="chain_trans_front_right">
    <type>position_controllers/JointTrajectoryController</type>
    <joint name="chains_joint_front_right">
      <hardwareInterface>PositionJointInterface</hardwareInterface>
    </joint>
    <actuator name="chain_motor_front_right">
      <hardwareInterface>PositionJointInterface</hardwareInterface>
      <mechanicalReduction>10</mechanicalReduction>
    </actuator>
  </transmission>
  <link name="chains_loose_back_left">
    <visual>
      <geometry>
        <mesh filename="package://iai_sherpa_donkey/meshes/Loose_Wheel.dae"/>
      </geometry>
    </visual>
    <collision>
      <geometry>
        <mesh filename="package://iai_sherpa_donkey/meshes/Loose_Wheel_Col.dae"/>
      </geometry>
    </collision>
    <inertial>
      <origin rpy="0 0 0" xyz="0 0 0"/>
      <mass value="0.5"/>
      <inertia ixx="0.001" ixy="0.0" ixz="0.0" iyy="0.001" iyz="0.0" izz="0.001"/>
    </inertial>
  </link>
  <joint name="chains_joint_back_left" type="revolute">
    <parent link="base_link"/>
    <child link="chains_loose_back_left"/>
    <origin rpy="3.14159393311 3.14159393311 0.0" xyz="-0.348821163177 0.503306388855 -0.26314997673"/>
    <limit effort="-1" lower="1." upper="2." velocity="-1"/>
    <axis xyz="0 -1 0"/>
  </joint>
  <transmission name="chain_trans_back_left">
    <type>position_controllers/JointTrajectoryController</type>
    <joint name="chains_joint_back_left">
      <hardwareInterface>PositionJointInterface</hardwareInterface>
    </joint>
    <actuator name="chain_motor_back_left">
      <hardwareInterface>PositionJointInterface</hardwareInterface>
      <mechanicalReduction>10</mechanicalReduction>
    </actuator>
  </transmission>
  <link name="chains_loose_back_right">
    <visual>
      <geometry>
        <mesh filename="package://iai_sherpa_donkey/meshes/Loose_Wheel.dae"/>
      </geometry>
    </visual>
    <collision>
      <geometry>
        <mesh filename="package://iai_sherpa_donkey/meshes/Loose_Wheel_Col.dae"/>
      </geometry>
    </collision>
    <inertial>
      <origin rpy="0 0 0" xyz="0 0 0"/>
      <mass value="0.5"/>
      <inertia ixx="0.001" ixy="0.0" ixz="0.0" iyy="0.001" iyz="0.0" izz="0.001"/>
    </inertial>
  </link>
  <joint name="chains_joint_back_right" type="revolute">
    <parent link="base_link"/>
    <child link="chains_loose_back_right"/>
    <origin rpy="0.0 3.14159393311 0.0" xyz="-0.348821163177 -0.503306388855 -0.26314997673"/>
    <limit effort="-1" lower="1." upper="2." velocity="-1"/>
    <axis xyz="0 1 0"/>
  </joint>
  <transmission name="chain_trans_back_right">
    <type>position_controllers/JointTrajectoryController</type>
    <joint name="chains_joint_back_right">
      <hardwareInterface>PositionJointInterface</hardwareInterface>
    </joint>
    <actuator name="chain_motor_back_right">
      <hardwareInterface>PositionJointInterface</hardwareInterface>
      <mechanicalReduction>10</mechanicalReduction>
    </actuator>
  </transmission>
  <link name="base_link">
    <!--MAIN_BODY-->
    <visual>
      <origin rpy="0 0 0" xyz="0 0 0"/>
      <geometry>
        <mesh filename="package://iai_sherpa_donkey/meshes/Body.dae"/>
      </geometry>
    </visual>
    <collision>
      <origin rpy="0 0 0" xyz="0 0 0"/>
      <geometry>
        <mesh filename="package://iai_sherpa_donkey/meshes/Body.dae"/>
      </geometry>
    </collision>
    <!--LEFT_CHAINS-->
    <visual>
      <origin rpy="0 0 0" xyz="0.16442573070526123 0.3477001190185547 -0.2631499767303467"/>
      <geometry>
        <mesh filename="package://iai_sherpa_donkey/meshes/Main_Wheel.dae"/>
      </geometry>
    </visual>
    <visual>
      <origin rpy="0 0 0" xyz="0.16442573070526123 -0.3477001190185547 -0.2631499767303467"/>
      <geometry>
        <mesh filename="package://iai_sherpa_donkey/meshes/Main_Wheel.dae"/>
      </geometry>
    </visual>
    <collision>
      <origin rpy="0 0 0" xyz="0.16442573070526123 0.3477001190185547 -0.2631499767303467"/>
      <geometry>
        <mesh filename="package://iai_sherpa_donkey/meshes/Main_Wheel.dae"/>
      </geometry>
    </collision>
    <collision>
      <origin rpy="0 0 0" xyz="0.16442573070526123 -0.3477001190185547 -0.2631499767303467"/>
      <geometry>
        <mesh filename="package://iai_sherpa_donkey/meshes/Main_Wheel.dae"/>
      </geometry>
    </collision>
    <!--
        <collision>
        <geometry>
            <mesh filename="package://iai_sherpa_donkey/meshes/Full_Body_Col.dae"/>
        </geometry>
            <origin xyz="0.004205834120512009 -8.124277428578353e-08 0.4054466485977173" rpy="0 0 0" />
        </collision>
	-->
    <inertial>
      <!--       
        <origin xyz="0.0 0 0.15" rpy="0 0 0"/>
	-->
      <origin rpy="0 0 0" xyz="0.2 0 -0.1"/>
      <mass value="50"/>
      <inertia ixx="0.75" ixy="0.0" ixz="0.0" iyy="0.75" iyz="0.0" izz="0.75"/>
    </inertial>
  </link>
  <link name="base_footprint">
    <!-- visual -->
    <!-- collision -->
    <!-- inertial -->
    <inertial>
      <origin rpy="0 0 0" xyz="0 0 0.03"/>
      <!-- FIXME starting higher to avoid collision-->
      <mass value="0.1"/>
      <!--
	-->
      <inertia ixx="0.01" ixy="0.0" ixz="0.0" iyy="0.01" iyz="0.0" izz="0.01"/>
    </inertial>
  </link>
  <joint name="base_footprint_base_link_joint" type="fixed">
    <parent link="base_footprint"/>
    <child link="base_link"/>
    <origin rpy="0 0 0" xyz="0 0 0.4054466485977173"/>
  </joint>
  <link name="wheel_front_left">
    <collision>
      <origin rpy="1.57079696655 0 0" xyz="0 0 0"/>
      <geometry>
        <cylinder length="0.125" radius="0.17"/>
        <!--
            <cylinder radius="0.17" length="0.125"/>
            -->
      </geometry>
    </collision>
    <inertial>
      <origin rpy="0 0 0" xyz="0 0 0"/>
      <mass value="4"/>
      <!-- 1 -->
      <inertia ixx=".005" ixy="0.0" ixz="0.0" iyy=".005" iyz="0.0" izz=".005"/>
    </inertial>
  </link>
  <gazebo reference="wheel_front_left">
    <mu1>01.</mu1>
    <mu2>1</mu2>
    <kp>3000</kp>
    <kd>10000</kd>
    <!--
	  <kp>10000</kp>
	  <kd>10000</kd>
	  -->
  </gazebo>
  <joint name="wheel_joint_front_left" type="continuous">
    <parent link="base_link"/>
    <child link="wheel_front_left"/>
    <origin rpy="0 0 0" xyz="0.696425437927 0.503306388855 -0.26314997673"/>
    <limit effort="400" lower="-2" upper="2" velocity="100"/>
    <axis xyz="0 1 0"/>
  </joint>
  <transmission name="wheel_trans_front_left">
    <type>transmission_interface/SimpleTransmission</type>
    <joint name="wheel_joint_front_left">
      <hardwareInterface>EffortJointInterface</hardwareInterface>
    </joint>
    <actuator name="wheel_motor_front_left">
      <hardwareInterface>EffortJointInterface</hardwareInterface>
      <mechanicalReduction>1</mechanicalReduction>
    </actuator>
  </transmission>
  <link name="wheel_front_right">
    <collision>
      <origin rpy="1.57079696655 0 0" xyz="0 0 0"/>
      <geometry>
        <cylinder length="0.125" radius="0.17"/>
        <!--
            <cylinder radius="0.17" length="0.125"/>
            -->
      </geometry>
    </collision>
    <inertial>
      <origin rpy="0 0 0" xyz="0 0 0"/>
      <mass value="4"/>
      <!-- 1 -->
      <inertia ixx=".005" ixy="0.0" ixz="0.0" iyy=".005" iyz="0.0" izz=".005"/>
    </inertial>
  </link>
  <gazebo reference="wheel_front_right">
    <mu1>01.</mu1>
    <mu2>1</mu2>
    <kp>3000</kp>
    <kd>10000</kd>
    <!--
	  <kp>10000</kp>
	  <kd>10000</kd>
	  -->
  </gazebo>
  <joint name="wheel_joint_front_right" type="continuous">
    <parent link="base_link"/>
    <child link="wheel_front_right"/>
    <origin rpy="0 0 0" xyz="0.696425437927 -0.503306388855 -0.26314997673"/>
    <limit effort="400" lower="-2" upper="2" velocity="100"/>
    <axis xyz="0 1 0"/>
  </joint>
  <transmission name="wheel_trans_front_right">
    <type>transmission_interface/SimpleTransmission</type>
    <joint name="wheel_joint_front_right">
      <hardwareInterface>EffortJointInterface</hardwareInterface>
    </joint>
    <actuator name="wheel_motor_front_right">
      <hardwareInterface>EffortJointInterface</hardwareInterface>
      <mechanicalReduction>1</mechanicalReduction>
    </actuator>
  </transmission>
  <link name="wheel_back_left">
    <collision>
      <origin rpy="1.57079696655 0 0" xyz="0 0 0"/>
      <geometry>
        <cylinder length="0.125" radius="0.17"/>
        <!--
            <cylinder radius="0.17" length="0.125"/>
            -->
      </geometry>
    </collision>
    <inertial>
      <origin rpy="0 0 0" xyz="0 0 0"/>
      <mass value="4"/>
      <!-- 1 -->
      <inertia ixx=".005" ixy="0.0" ixz="0.0" iyy=".005" iyz="0.0" izz=".005"/>
    </inertial>
  </link>
  <gazebo reference="wheel_back_left">
    <mu1>01.</mu1>
    <mu2>1</mu2>
    <kp>3000</kp>
    <kd>10000</kd>
    <!--
	  <kp>10000</kp>
	  <kd>10000</kd>
	  -->
  </gazebo>
  <joint name="wheel_joint_back_left" type="continuous">
    <parent link="base_link"/>
    <child link="wheel_back_left"/>
    <origin rpy="0 0 0" xyz="-0.348821163177 0.503306388855 -0.26314997673"/>
    <limit effort="400" lower="-2" upper="2" velocity="100"/>
    <axis xyz="0 1 0"/>
  </joint>
  <transmission name="wheel_trans_back_left">
    <type>transmission_interface/SimpleTransmission</type>
    <joint name="wheel_joint_back_left">
      <hardwareInterface>EffortJointInterface</hardwareInterface>
    </joint>
    <actuator name="wheel_motor_back_left">
      <hardwareInterface>EffortJointInterface</hardwareInterface>
      <mechanicalReduction>1</mechanicalReduction>
    </actuator>
  </transmission>
  <link name="wheel_back_right">
    <collision>
      <origin rpy="1.57079696655 0 0" xyz="0 0 0"/>
      <geometry>
        <cylinder length="0.125" radius="0.17"/>
        <!--
            <cylinder radius="0.17" length="0.125"/>
            -->
      </geometry>
    </collision>
    <inertial>
      <origin rpy="0 0 0" xyz="0 0 0"/>
      <mass value="4"/>
      <!-- 1 -->
      <inertia ixx=".005" ixy="0.0" ixz="0.0" iyy=".005" iyz="0.0" izz=".005"/>
    </inertial>
  </link>
  <gazebo reference="wheel_back_right">
    <mu1>01.</mu1>
    <mu2>1</mu2>
    <kp>3000</kp>
    <kd>10000</kd>
    <!--
	  <kp>10000</kp>
	  <kd>10000</kd>
	  -->
  </gazebo>
  <joint name="wheel_joint_back_right" type="continuous">
    <parent link="base_link"/>
    <child link="wheel_back_right"/>
    <origin rpy="0 0 0" xyz="-0.348821163177 -0.503306388855 -0.26314997673"/>
    <limit effort="400" lower="-2" upper="2" velocity="100"/>
    <axis xyz="0 1 0"/>
  </joint>
  <transmission name="wheel_trans_back_right">
    <type>transmission_interface/SimpleTransmission</type>
    <joint name="wheel_joint_back_right">
      <hardwareInterface>EffortJointInterface</hardwareInterface>
    </joint>
    <actuator name="wheel_motor_back_right">
      <hardwareInterface>EffortJointInterface</hardwareInterface>
      <mechanicalReduction>1</mechanicalReduction>
    </actuator>
  </transmission>
  <gazebo reference="cam_left">
    <sensor name="cam_left_camera" type="camera">
      <pose>0 0 0 3.141592654 0 0 </pose>
      <update_rate>30.0</update_rate>
      <camera name="cam_left_cam">
        <horizontal_fov>1.3962634</horizontal_fov>
        <image>
          <width>1024</width>
          <height>768</height>
          <format>R8G8B8</format>
        </image>
        <clip>
          <near>0.25</near>
          <far>1000</far>
        </clip>
        <noise>
          <type>gaussian</type>
          <!-- Noise is sampled independently per pixel on each frame.  
               That pixel's noise value is added to each of its color
               channels, which at that point lie in the range [0,1]. -->
          <mean>0.0</mean>
          <stddev>0.007</stddev>
        </noise>
      </camera>
      <plugin filename="libgazebo_ros_camera.so" name="camera_controller">
        <alwaysOn>true</alwaysOn>
        <updateRate>0.0</updateRate>
        <cameraName>cam_left_camera</cameraName>
        <imageTopicName>image_raw</imageTopicName>
        <cameraInfoTopicName>camera_info</cameraInfoTopicName>
        <frameName>cam_left</frameName>
        <hackBaseline>0.07</hackBaseline>
        <distortionK1>0.0</distortionK1>
        <distortionK2>0.0</distortionK2>
        <distortionK3>0.0</distortionK3>
        <distortionT1>0.0</distortionT1>
        <distortionT2>0.0</distortionT2>
      </plugin>
    </sensor>
  </gazebo>
  <joint name="hokuyo_joint" type="fixed">
    <axis xyz="0 1 0"/>
    <origin rpy="0 0.1 0" xyz="0.43 0.0 0.0010"/>
    <parent link="base_link"/>
    <child link="hokuyo_link"/>
  </joint>
  <link name="hokuyo_link">
    <collision>
      <origin rpy="0 0 0" xyz="0 0 0"/>
      <geometry>
        <box size="0.1 0.1 0.1"/>
      </geometry>
    </collision>
    <visual>
      <origin rpy="0 0 0" xyz="0 0 0"/>
      <geometry>
        <mesh filename="package://iai_sherpa_donkey/meshes/tilting_hokuyo.dae"/>
      </geometry>
    </visual>
    <inertial>
      <mass value="1e-5"/>
      <origin rpy="0 0 0" xyz="0 0 0"/>
      <inertia ixx="1e-6" ixy="0" ixz="0" iyy="1e-6" iyz="0" izz="1e-6"/>
    </inertial>
  </link>
  <gazebo reference="hokuyo_link">
    <sensor name="head_hokuyo_sensor" type="gpu_ray">
      <pose>0 0 0 0 0 0</pose>
      <visualize>false</visualize>
      <update_rate>40</update_rate>
      <ray>
        <scan>
          <horizontal>
            <samples>720</samples>
            <resolution>1</resolution>
            <min_angle>-0.4</min_angle>
            <max_angle>0.4</max_angle>
          </horizontal>
        </scan>
        <range>
          <min>0.10</min>
          <max>10.0</max>
          <resolution>0.1</resolution>
        </range>
        <noise>
          <type>gaussian</type>
          <!-- Noise parameters based on published spec for Hokuyo laser
               achieving "+-30mm" accuracy at range < 10m.  A mean of 0.0m and
               stddev of 0.01m will put 99.7% of samples within 0.03m of the true
               reading. -->
          <mean>0.0</mean>
          <stddev>0.01</stddev>
        </noise>
      </ray>
      <plugin filename="libgazebo_ros_gpu_laser.so" name="gazebo_ros_head_hokuyo_controller">
        <topicName>/donkey/rrbot/laser/scan</topicName>
        <frameName>hokuyo_link</frameName>
      </plugin>
    </sensor>
  </gazebo>
  <gazebo reference="cam_right">
    <sensor name="cam_right_camera" type="camera">
      <pose>0 0 0 3.141592654 0 0 </pose>
      <update_rate>30.0</update_rate>
      <camera name="cam_right_cam">
        <horizontal_fov>1.3962634</horizontal_fov>
        <image>
          <width>1024</width>
          <height>768</height>
          <format>R8G8B8</format>
        </image>
        <clip>
          <near>0.25</near>
          <far>1000</far>
        </clip>
        <noise>
          <type>gaussian</type>
          <!-- Noise is sampled independently per pixel on each frame.  
               That pixel's noise value is added to each of its color
               channels, which at that point lie in the range [0,1]. -->
          <mean>0.0</mean>
          <stddev>0.007</stddev>
        </noise>
      </camera>
      <plugin filename="libgazebo_ros_camera.so" name="camera_controller">
        <alwaysOn>true</alwaysOn>
        <updateRate>0.0</updateRate>
        <cameraName>cam_right_camera</cameraName>
        <imageTopicName>image_raw</imageTopicName>
        <cameraInfoTopicName>camera_info</cameraInfoTopicName>
        <frameName>cam_right</frameName>
        <hackBaseline>0.07</hackBaseline>
        <distortionK1>0.0</distortionK1>
        <distortionK2>0.0</distortionK2>
        <distortionK3>0.0</distortionK3>
        <distortionT1>0.0</distortionT1>
        <distortionT2>0.0</distortionT2>
      </plugin>
    </sensor>
  </gazebo>
  <gazebo>
    <plugin filename="libgazebo_ros_control.so" name="donkey_ros_control">
      <controlPeriod>0.001</controlPeriod>
      <robotParam>robot_description</robotParam>
      <!--
            <robotNamespace>$(arg prefix)</robotNamespace>
            <robotSimType>sherpa_donkey_control/SherpaDonkeyHWSim</robotSimType>
	    
	    -->
    </plugin>
  </gazebo>
  <gazebo>
    <plugin filename="libiai_donkey_move_plugin.so" name="donkey_controller">
      <commandTopic>cmd_vel</commandTopic>
      <odometryTopic>world</odometryTopic>
      <odometryFrame>world</odometryFrame>
      <odometryRate>20.0</odometryRate>
      <robotBaseFrame>base_footprint</robotBaseFrame>
    </plugin>
  </gazebo>
</robot>
